[2022-11-01 08:38:42,767: INFO/MainProcess] Connected to redis://redis:6379//
[2022-11-01 08:38:42,820: INFO/MainProcess] mingle: searching for neighbors
[2022-11-01 08:38:43,929: INFO/MainProcess] mingle: all alone
[2022-11-01 08:38:43,988: INFO/MainProcess] celery@d2b98ff317b8 ready.
[2022-11-01 08:39:04,018: INFO/MainProcess] Received task: tasks.trip.tasks.predict_ride[8da9857d-92ae-486b-aa59-9ab1da1b8192]
[2022-11-01 08:39:04,049: INFO/MainProcess] Task tasks.trip.tasks.predict_ride[8da9857d-92ae-486b-aa59-9ab1da1b8192] succeeded in 0.02153879199977382s: {'duration': 12.785509620119132, 'reply_code': 0, 'timings': {'feature_prepare': 0, 'model_predict': 14}}
[2022-11-01 08:40:33,404: WARNING/MainProcess] consumer: Connection to broker lost. Trying to re-establish the connection...
Traceback (most recent call last):
  File "/home/docker/miniconda/envs/venv/lib/python3.8/site-packages/celery/worker/consumer/consumer.py", line 318, in start
    blueprint.start(self)
  File "/home/docker/miniconda/envs/venv/lib/python3.8/site-packages/celery/bootsteps.py", line 119, in start
    step.start(parent)
  File "/home/docker/miniconda/envs/venv/lib/python3.8/site-packages/celery/worker/consumer/consumer.py", line 596, in start
    c.loop(*c.loop_args())
  File "/home/docker/miniconda/envs/venv/lib/python3.8/site-packages/celery/worker/loops.py", line 83, in asynloop
    next(loop)
  File "/home/docker/miniconda/envs/venv/lib/python3.8/site-packages/kombu/asynchronous/hub.py", line 364, in create_loop
    cb(*cbargs)
  File "/home/docker/miniconda/envs/venv/lib/python3.8/site-packages/kombu/transport/redis.py", line 1083, in on_readable
    self.cycle.on_readable(fileno)
  File "/home/docker/miniconda/envs/venv/lib/python3.8/site-packages/kombu/transport/redis.py", line 354, in on_readable
    chan.handlers[type]()
  File "/home/docker/miniconda/envs/venv/lib/python3.8/site-packages/kombu/transport/redis.py", line 688, in _receive
    ret.append(self._receive_one(c))
  File "/home/docker/miniconda/envs/venv/lib/python3.8/site-packages/kombu/transport/redis.py", line 698, in _receive_one
    response = c.parse_response()
  File "/home/docker/miniconda/envs/venv/lib/python3.8/site-packages/redis/client.py", line 3185, in parse_response
    response = self._execute(conn, conn.read_response)
  File "/home/docker/miniconda/envs/venv/lib/python3.8/site-packages/redis/client.py", line 3159, in _execute
    return command(*args, **kwargs)
  File "/home/docker/miniconda/envs/venv/lib/python3.8/site-packages/redis/connection.py", line 700, in read_response
    response = self._parser.read_response()
  File "/home/docker/miniconda/envs/venv/lib/python3.8/site-packages/redis/connection.py", line 310, in read_response
    response = self._buffer.readline()
  File "/home/docker/miniconda/envs/venv/lib/python3.8/site-packages/redis/connection.py", line 242, in readline
    self._read_from_socket()
  File "/home/docker/miniconda/envs/venv/lib/python3.8/site-packages/redis/connection.py", line 187, in _read_from_socket
    raise ConnectionError(SERVER_CLOSED_CONNECTION_ERROR)
redis.exceptions.ConnectionError: Connection closed by server.
